INFO:root:faces: 1 at 2019-11-16 22:57:44.537857
INFO:root:faces: 0 at 2019-11-16 22:57:48.384998
INFO:root:faces: 1 at 2019-11-16 22:57:51.757481
INFO:root:faces: 0 at 2019-11-16 22:57:58.956967
INFO:root:faces: 1 at 2019-11-16 22:58:01.271837
INFO:root:faces: 0 at 2019-11-16 22:58:03.614967
INFO:root:faces: 1 at 2019-11-16 22:58:04.298630
INFO:root:faces: 0 at 2019-11-16 22:58:06.088579
INFO:root:faces: 1 at 2019-11-16 22:58:07.124536
INFO:root:faces: 2 at 2019-11-16 22:58:08.146801
INFO:root:faces: 1 at 2019-11-16 22:58:08.488994
INFO:root:faces: 1 at 2019-11-16 22:59:16.895240
INFO:root:faces: 0 at 2019-11-16 22:59:19.712128
INFO:root:faces: 1 at 2019-11-16 22:59:21.770856
INFO:root:faces: 2 at 2019-11-16 22:59:24.198027
INFO:root:faces: 1 at 2019-11-16 22:59:24.569076
INFO:root:faces: 0 at 2019-11-16 22:59:26.746989
INFO:root:faces: 2 at 2019-11-16 22:59:31.195677
INFO:root:faces: 1 at 2019-11-16 22:59:31.555375
INFO:root:faces: 2 at 2019-11-16 22:59:34.118037
INFO:root:faces: 1 at 2019-11-16 22:59:34.434391
INFO:root:faces: 0 at 2019-11-16 22:59:34.795230
INFO:root:faces: 1 at 2019-11-16 22:59:37.155969
INFO:root:faces: 0 at 2019-11-16 22:59:40.021142
INFO:root:faces: 1 at 2019-11-16 22:59:42.470319
INFO:root:faces: 2 at 2019-11-16 22:59:43.206469
INFO:root:faces: 1 at 2019-11-16 22:59:43.948458
INFO:root:faces: 1 at 2019-11-16 23:00:39.395073
INFO:root:faces: 0 at 2019-11-16 23:00:41.611111
INFO:root:faces: 1 at 2019-11-16 23:00:41.997353
INFO:root:faces: 0 at 2019-11-16 23:00:42.387683
INFO:root:faces: 1 at 2019-11-16 23:00:43.822362
INFO:root:faces: 0 at 2019-11-16 23:00:45.953706
INFO:root:faces: 1 at 2019-11-16 23:00:46.255766
INFO:root:faces: 0 at 2019-11-16 23:00:46.602848
INFO:root:faces: 1 at 2019-11-16 23:00:48.006097
INFO:root:faces: 2 at 2019-11-16 23:00:51.649847
INFO:root:faces: 1 at 2019-11-16 23:00:52.012190
INFO:root:faces: 2 at 2019-11-16 23:00:53.029348
INFO:root:faces: 1 at 2019-11-16 23:00:53.372977
INFO:root:faces: 0 at 2019-11-16 23:00:54.140581
INFO:root:faces: 1 at 2019-11-16 23:00:54.877925
INFO:google_auth_oauthlib.flow:"GET /?state=RoWh6vkWamDVFWR77fU4xweEWlVcX4&code=4/tQHh79TV1io9b0bMiQs8m06N0TBA4vgpHQgBXq293BqpXvTjoDzuZoxyFtUt2e4KwW7znmNqesB_CzxcOIXLOv4&scope=https://www.googleapis.com/auth/drive.metadata.readonly HTTP/1.1" 200 65
WARNING:googleapiclient.discovery_cache:file_cache is unavailable when using oauth2client >= 4.0.0 or google-auth
Traceback (most recent call last):
  File "c:\users\avantikadg\appdata\local\programs\python\python36\lib\site-packages\googleapiclient\discovery_cache\__init__.py", line 36, in autodetect
    from google.appengine.api import memcache
ModuleNotFoundError: No module named 'google.appengine'

During handling of the above exception, another exception occurred:

Traceback (most recent call last):
  File "c:\users\avantikadg\appdata\local\programs\python\python36\lib\site-packages\googleapiclient\discovery_cache\file_cache.py", line 33, in <module>
    from oauth2client.contrib.locked_file import LockedFile
ModuleNotFoundError: No module named 'oauth2client'

During handling of the above exception, another exception occurred:

Traceback (most recent call last):
  File "c:\users\avantikadg\appdata\local\programs\python\python36\lib\site-packages\googleapiclient\discovery_cache\file_cache.py", line 37, in <module>
    from oauth2client.locked_file import LockedFile
ModuleNotFoundError: No module named 'oauth2client'

During handling of the above exception, another exception occurred:

Traceback (most recent call last):
  File "c:\users\avantikadg\appdata\local\programs\python\python36\lib\site-packages\googleapiclient\discovery_cache\__init__.py", line 41, in autodetect
    from . import file_cache
  File "c:\users\avantikadg\appdata\local\programs\python\python36\lib\site-packages\googleapiclient\discovery_cache\file_cache.py", line 41, in <module>
    'file_cache is unavailable when using oauth2client >= 4.0.0 or google-auth')
ImportError: file_cache is unavailable when using oauth2client >= 4.0.0 or google-auth
INFO:googleapiclient.discovery:URL being requested: GET https://www.googleapis.com/discovery/v1/apis/drive/v3/rest
INFO:googleapiclient.discovery:URL being requested: GET https://www.googleapis.com/drive/v3/files?pageSize=10&fields=nextPageToken%2C+files%28id%2C+name%29&alt=json
WARNING:googleapiclient.discovery_cache:file_cache is unavailable when using oauth2client >= 4.0.0 or google-auth
Traceback (most recent call last):
  File "c:\users\avantikadg\appdata\local\programs\python\python36\lib\site-packages\googleapiclient\discovery_cache\__init__.py", line 36, in autodetect
    from google.appengine.api import memcache
ModuleNotFoundError: No module named 'google.appengine'

During handling of the above exception, another exception occurred:

Traceback (most recent call last):
  File "c:\users\avantikadg\appdata\local\programs\python\python36\lib\site-packages\googleapiclient\discovery_cache\file_cache.py", line 33, in <module>
    from oauth2client.contrib.locked_file import LockedFile
ModuleNotFoundError: No module named 'oauth2client'

During handling of the above exception, another exception occurred:

Traceback (most recent call last):
  File "c:\users\avantikadg\appdata\local\programs\python\python36\lib\site-packages\googleapiclient\discovery_cache\file_cache.py", line 37, in <module>
    from oauth2client.locked_file import LockedFile
ModuleNotFoundError: No module named 'oauth2client'

During handling of the above exception, another exception occurred:

Traceback (most recent call last):
  File "c:\users\avantikadg\appdata\local\programs\python\python36\lib\site-packages\googleapiclient\discovery_cache\__init__.py", line 41, in autodetect
    from . import file_cache
  File "c:\users\avantikadg\appdata\local\programs\python\python36\lib\site-packages\googleapiclient\discovery_cache\file_cache.py", line 41, in <module>
    'file_cache is unavailable when using oauth2client >= 4.0.0 or google-auth')
ImportError: file_cache is unavailable when using oauth2client >= 4.0.0 or google-auth
INFO:googleapiclient.discovery:URL being requested: GET https://www.googleapis.com/discovery/v1/apis/drive/v3/rest
INFO:googleapiclient.discovery:URL being requested: GET https://www.googleapis.com/drive/v3/files?pageSize=10&fields=nextPageToken%2C+files%28id%2C+name%29&alt=json
INFO:google_auth_oauthlib.flow:"GET /?state=Hs393OXQXLcH445GGqnux7GlujnNEQ&code=4/tQFijjpEpdyNvZHBGtMRVTO74xCPQQxfsm3r8fdISkuTIsTIFxcSc6NnFKHwB579R0V_Qwn9jBO090YV3kUXr90&scope=https://www.googleapis.com/auth/drive.metadata.readonly HTTP/1.1" 200 65
WARNING:googleapiclient.discovery_cache:file_cache is unavailable when using oauth2client >= 4.0.0 or google-auth
Traceback (most recent call last):
  File "c:\users\avantikadg\appdata\local\programs\python\python36\lib\site-packages\googleapiclient\discovery_cache\__init__.py", line 36, in autodetect
    from google.appengine.api import memcache
ModuleNotFoundError: No module named 'google.appengine'

During handling of the above exception, another exception occurred:

Traceback (most recent call last):
  File "c:\users\avantikadg\appdata\local\programs\python\python36\lib\site-packages\googleapiclient\discovery_cache\file_cache.py", line 33, in <module>
    from oauth2client.contrib.locked_file import LockedFile
ModuleNotFoundError: No module named 'oauth2client'

During handling of the above exception, another exception occurred:

Traceback (most recent call last):
  File "c:\users\avantikadg\appdata\local\programs\python\python36\lib\site-packages\googleapiclient\discovery_cache\file_cache.py", line 37, in <module>
    from oauth2client.locked_file import LockedFile
ModuleNotFoundError: No module named 'oauth2client'

During handling of the above exception, another exception occurred:

Traceback (most recent call last):
  File "c:\users\avantikadg\appdata\local\programs\python\python36\lib\site-packages\googleapiclient\discovery_cache\__init__.py", line 41, in autodetect
    from . import file_cache
  File "c:\users\avantikadg\appdata\local\programs\python\python36\lib\site-packages\googleapiclient\discovery_cache\file_cache.py", line 41, in <module>
    'file_cache is unavailable when using oauth2client >= 4.0.0 or google-auth')
ImportError: file_cache is unavailable when using oauth2client >= 4.0.0 or google-auth
INFO:googleapiclient.discovery:URL being requested: GET https://www.googleapis.com/discovery/v1/apis/drive/v3/rest
INFO:googleapiclient.discovery:URL being requested: GET https://www.googleapis.com/drive/v3/files?pageSize=10&fields=nextPageToken%2C+files%28id%2C+name%29&alt=json
WARNING:googleapiclient.discovery_cache:file_cache is unavailable when using oauth2client >= 4.0.0 or google-auth
Traceback (most recent call last):
  File "c:\users\avantikadg\appdata\local\programs\python\python36\lib\site-packages\googleapiclient\discovery_cache\__init__.py", line 36, in autodetect
    from google.appengine.api import memcache
ModuleNotFoundError: No module named 'google.appengine'

During handling of the above exception, another exception occurred:

Traceback (most recent call last):
  File "c:\users\avantikadg\appdata\local\programs\python\python36\lib\site-packages\googleapiclient\discovery_cache\file_cache.py", line 33, in <module>
    from oauth2client.contrib.locked_file import LockedFile
ModuleNotFoundError: No module named 'oauth2client'

During handling of the above exception, another exception occurred:

Traceback (most recent call last):
  File "c:\users\avantikadg\appdata\local\programs\python\python36\lib\site-packages\googleapiclient\discovery_cache\file_cache.py", line 37, in <module>
    from oauth2client.locked_file import LockedFile
ModuleNotFoundError: No module named 'oauth2client'

During handling of the above exception, another exception occurred:

Traceback (most recent call last):
  File "c:\users\avantikadg\appdata\local\programs\python\python36\lib\site-packages\googleapiclient\discovery_cache\__init__.py", line 41, in autodetect
    from . import file_cache
  File "c:\users\avantikadg\appdata\local\programs\python\python36\lib\site-packages\googleapiclient\discovery_cache\file_cache.py", line 41, in <module>
    'file_cache is unavailable when using oauth2client >= 4.0.0 or google-auth')
ImportError: file_cache is unavailable when using oauth2client >= 4.0.0 or google-auth
INFO:googleapiclient.discovery:URL being requested: GET https://www.googleapis.com/discovery/v1/apis/drive/v3/rest
INFO:googleapiclient.discovery:URL being requested: GET https://www.googleapis.com/drive/v3/files?pageSize=10&fields=nextPageToken%2C+files%28id%2C+name%29&alt=json
WARNING:googleapiclient.discovery_cache:file_cache is unavailable when using oauth2client >= 4.0.0 or google-auth
Traceback (most recent call last):
  File "c:\users\avantikadg\appdata\local\programs\python\python36\lib\site-packages\googleapiclient\discovery_cache\__init__.py", line 36, in autodetect
    from google.appengine.api import memcache
ModuleNotFoundError: No module named 'google.appengine'

During handling of the above exception, another exception occurred:

Traceback (most recent call last):
  File "c:\users\avantikadg\appdata\local\programs\python\python36\lib\site-packages\googleapiclient\discovery_cache\file_cache.py", line 33, in <module>
    from oauth2client.contrib.locked_file import LockedFile
ModuleNotFoundError: No module named 'oauth2client'

During handling of the above exception, another exception occurred:

Traceback (most recent call last):
  File "c:\users\avantikadg\appdata\local\programs\python\python36\lib\site-packages\googleapiclient\discovery_cache\file_cache.py", line 37, in <module>
    from oauth2client.locked_file import LockedFile
ModuleNotFoundError: No module named 'oauth2client'

During handling of the above exception, another exception occurred:

Traceback (most recent call last):
  File "c:\users\avantikadg\appdata\local\programs\python\python36\lib\site-packages\googleapiclient\discovery_cache\__init__.py", line 41, in autodetect
    from . import file_cache
  File "c:\users\avantikadg\appdata\local\programs\python\python36\lib\site-packages\googleapiclient\discovery_cache\file_cache.py", line 41, in <module>
    'file_cache is unavailable when using oauth2client >= 4.0.0 or google-auth')
ImportError: file_cache is unavailable when using oauth2client >= 4.0.0 or google-auth
INFO:googleapiclient.discovery:URL being requested: GET https://www.googleapis.com/discovery/v1/apis/drive/v3/rest
INFO:googleapiclient.discovery:URL being requested: GET https://www.googleapis.com/drive/v3/files?pageSize=10&fields=nextPageToken%2C+files%28id%2C+name%29&alt=json
WARNING:googleapiclient.discovery_cache:file_cache is unavailable when using oauth2client >= 4.0.0 or google-auth
Traceback (most recent call last):
  File "c:\users\avantikadg\appdata\local\programs\python\python36\lib\site-packages\googleapiclient\discovery_cache\__init__.py", line 36, in autodetect
    from google.appengine.api import memcache
ModuleNotFoundError: No module named 'google.appengine'

During handling of the above exception, another exception occurred:

Traceback (most recent call last):
  File "c:\users\avantikadg\appdata\local\programs\python\python36\lib\site-packages\googleapiclient\discovery_cache\file_cache.py", line 33, in <module>
    from oauth2client.contrib.locked_file import LockedFile
ModuleNotFoundError: No module named 'oauth2client'

During handling of the above exception, another exception occurred:

Traceback (most recent call last):
  File "c:\users\avantikadg\appdata\local\programs\python\python36\lib\site-packages\googleapiclient\discovery_cache\file_cache.py", line 37, in <module>
    from oauth2client.locked_file import LockedFile
ModuleNotFoundError: No module named 'oauth2client'

During handling of the above exception, another exception occurred:

Traceback (most recent call last):
  File "c:\users\avantikadg\appdata\local\programs\python\python36\lib\site-packages\googleapiclient\discovery_cache\__init__.py", line 41, in autodetect
    from . import file_cache
  File "c:\users\avantikadg\appdata\local\programs\python\python36\lib\site-packages\googleapiclient\discovery_cache\file_cache.py", line 41, in <module>
    'file_cache is unavailable when using oauth2client >= 4.0.0 or google-auth')
ImportError: file_cache is unavailable when using oauth2client >= 4.0.0 or google-auth
INFO:googleapiclient.discovery:URL being requested: GET https://www.googleapis.com/discovery/v1/apis/drive/v3/rest
INFO:googleapiclient.discovery:URL being requested: GET https://www.googleapis.com/drive/v3/files?pageSize=10&fields=nextPageToken%2C+files%28id%2C+name%29&alt=json
INFO:googleapiclient.discovery:URL being requested: POST https://www.googleapis.com/upload/drive/v3/files?fields=id&alt=json&uploadType=multipart
WARNING:googleapiclient.http:Encountered 403 Forbidden with reason "insufficientPermissions"
WARNING:googleapiclient.discovery_cache:file_cache is unavailable when using oauth2client >= 4.0.0 or google-auth
Traceback (most recent call last):
  File "c:\users\avantikadg\appdata\local\programs\python\python36\lib\site-packages\googleapiclient\discovery_cache\__init__.py", line 36, in autodetect
    from google.appengine.api import memcache
ModuleNotFoundError: No module named 'google.appengine'

During handling of the above exception, another exception occurred:

Traceback (most recent call last):
  File "c:\users\avantikadg\appdata\local\programs\python\python36\lib\site-packages\googleapiclient\discovery_cache\file_cache.py", line 33, in <module>
    from oauth2client.contrib.locked_file import LockedFile
ModuleNotFoundError: No module named 'oauth2client'

During handling of the above exception, another exception occurred:

Traceback (most recent call last):
  File "c:\users\avantikadg\appdata\local\programs\python\python36\lib\site-packages\googleapiclient\discovery_cache\file_cache.py", line 37, in <module>
    from oauth2client.locked_file import LockedFile
ModuleNotFoundError: No module named 'oauth2client'

During handling of the above exception, another exception occurred:

Traceback (most recent call last):
  File "c:\users\avantikadg\appdata\local\programs\python\python36\lib\site-packages\googleapiclient\discovery_cache\__init__.py", line 41, in autodetect
    from . import file_cache
  File "c:\users\avantikadg\appdata\local\programs\python\python36\lib\site-packages\googleapiclient\discovery_cache\file_cache.py", line 41, in <module>
    'file_cache is unavailable when using oauth2client >= 4.0.0 or google-auth')
ImportError: file_cache is unavailable when using oauth2client >= 4.0.0 or google-auth
INFO:googleapiclient.discovery:URL being requested: GET https://www.googleapis.com/discovery/v1/apis/drive/v3/rest
INFO:googleapiclient.discovery:URL being requested: GET https://www.googleapis.com/drive/v3/files?pageSize=10&fields=nextPageToken%2C+files%28id%2C+name%29&alt=json
INFO:googleapiclient.discovery:URL being requested: POST https://www.googleapis.com/upload/drive/v3/files?fields=id&alt=json&uploadType=multipart
WARNING:googleapiclient.http:Encountered 403 Forbidden with reason "insufficientPermissions"
